
(15594, 9)
Traceback (most recent call last):
  File "/usr/local/lib/python3.9/dist-packages/pandas/core/indexes/base.py", line 3621, in get_loc
    return self._engine.get_loc(casted_key)
  File "pandas/_libs/index.pyx", line 136, in pandas._libs.index.IndexEngine.get_loc
  File "pandas/_libs/index.pyx", line 163, in pandas._libs.index.IndexEngine.get_loc
  File "pandas/_libs/hashtable_class_helper.pxi", line 5198, in pandas._libs.hashtable.PyObjectHashTable.get_item
  File "pandas/_libs/hashtable_class_helper.pxi", line 5206, in pandas._libs.hashtable.PyObjectHashTable.get_item
KeyError: 'cos_sim'
The above exception was the direct cause of the following exception:
Traceback (most recent call last):
  File "/notebooks/code/exp059.py", line 828, in <module>
    main()
  File "/notebooks/code/exp059.py", line 714, in main
    data_2021 = data_2021[data_2021["cos_sim"]>0.6].reset_index(drop=True)
  File "/usr/local/lib/python3.9/dist-packages/pandas/core/frame.py", line 3505, in __getitem__
    indexer = self.columns.get_loc(key)
  File "/usr/local/lib/python3.9/dist-packages/pandas/core/indexes/base.py", line 3623, in get_loc
    raise KeyError(key) from err
KeyError: 'cos_sim'